Workbook
Name JB_A: 'J Book Items Cons.'!$A$5:$A$3381
Name JB_B: 'J Book Items Cons.'!$E$5:$E$3381
Name JB_F: 'J Book Items Cons.'!$F$5:$F$3381
Name JB_S: 'J Book Items Cons.'!$V$5:$V$3381
Name JB_U: 'J Book Items Cons.'!$X$5:$X$3381
Name JB_V: 'J Book Items Cons.'!$Y$5:$Y$3381
Name JB_W: 'J Book Items Cons.'!$Z$5:$Z$3381
Name JB_R: 'J Book Items Cons.'!$R$5:$R$3381
Name JB_N: 'J Book Items Cons.'!$N$5:$N$3381
Name JB_L: 'J Book Items Cons.'!$L$5:$L$3381
Name JB_27U: 'J Book Items Cons.'!$U$5:$U$3381
Name JB_27S: 'J Book Items Cons.'!$S$5:$S$3381

Sheet J Book Items Cons.
A1: J Book Items Consolidated
A2: Consolidated line-item budget data from SCN, OPN, OMN, NWCF, and USCG justification books
A4: Source Book | B4: Color of Money | C4: Line Item Number | D4: Line Item Title | E4: Bucket | F4: Bucket Sub Category | G4: Description | H4: Prior Years ($K) | I4: FY2024 ($K) | J4: FY2025 ($K) | K4: FY2025 Required ($K) | L4: FY2026 Request ($K) | M4: FY2026 Reconciliation ($K) | N4: FY2026 Total ($K) | O4: FY2026 Required ($K) | P4: FY2026 DAA Mandatory ($K) | Q4: FY2026 DAA Final Bill ($K) | R4: FY2026 DAA Enacted Total ($K) | S4: FY2027 Request ($K) | T4: FY2027 Mandatory Request ($K) | U4: FY2027 Total ($K) | V4: Row Type | W4: Parent Item | X4: Vessel Service | Y4: Vessel Category | Z4: Vessel Type | AA4: Vessel Hull | AB4: Citation | AC4: Source Page | AF4: Program Element Number | AG4: Project | AH4: Cost Element | AI4: Market | AJ4: Submarket | AK4: PE Description
A5: SCN | B5: Procurement | C5: 1045 | D5: COLUMBIA Class Submarine | E5: 1 | F5: Full ship DD&C | G5: MISSION: Strategic Deterrence. The COLUMBIA Class Program is an Acquisition Category (ACAT) ID Major Defense Acquisition Program (MDAP) to design, construct, and deliver a replacement for the OHIO Class Fleet Ballistic Missile Submarines (SSBNs), which begins retiring at a rate of one per year | I5: 0 | J5: 3364835 | L5: 3928828 | M5: 0 | N5: 3928828 | Q5: 3928828 | R5: 3928828 | S5: 10233832 | U5: 10233832 | V5: [PARENT] | X5: USN | Y5: Combatant Ships | Z5: Submarines | AA5: SSBN | AB5: P-40 Exhibit > LI 1045 > COLUMBIA Class Submarine | AC5: 31 | AF5: 1045 | AI5: Maritime Platforms & Systems | AJ5: Submarines - SSBN/SSGN | AK5: MISSION: Strategic Deterrence. The COLUMBIA Class Program is an Acquisition Category (ACAT) ID Major Defense Acquisition Program (MDAP) to design, construct, and deliver a replacement for the OHIO Class Fleet Ballistic Missile Submarines (SSBNs), which begins retiring at a rate of one per year beginning in 2027. The mission of the COLUMBIA SSBN is to maintain an appropriate state of readiness to assist in deterring nuclear attack on the United States and its allies. In the event deterrence should fail, the force must be capable of launching missiles against pre-planned or adaptively planned targets. To fulfill this mission COLUMBIA SSBNs must be capable of performing extended strategic deterrent patrols without requiring assistance or replenishment. It does not have a requirement for additional capabilities or other missions unrelated to survivable strategic nuclear deterrence. Armament: Torpedo Tubes Ballistic Missile Tubes Major Electronics: Trident D5 Strategic Weapons System Command, Control, Communications and Intelligence System - Open System Architecture - Twenty-three Subsystems Note: The FY 2026 request for COLUMBIA Class Submarine includes $8,994,594 thousand of discretionary funding and $1,925,892 thousand of mandatory (reconciliation) funding for a total of $10,920,486 thousand. While the total FY 2026 discretionary funding decreased by $1,426,814 million when compared to the FY 2026 funding in the FY 2025 submission ($10,421,408 thousand), the overall funding (mandatory plus discretionary) for COLUMBIA Class Submarine increased by $499,078 thousand when compared to the FY 2026 funding in the FY 2025 submission. FY2026 is the first year of incremental full funding for the third ship, SSBN 828. Additionally, FY2026 funds the COLUMBIA Class Program to the NAVSEA 05C's 2023 cost estimate and preliminary Build II (SSBN 828-832) contract negotiations. The FY2026 budget and P5 breakout also includes Cost to Complete for Build I (SSBN 826-827), however, funding is reflected in FY2027-2030. The budget also includes continuing Integrated Enterprise Plan (IEP) funding initiatives, material procurement for future ships, and funding for the Maritime Industrial Base (MIB) (previously referred to as the Submarine Industrial Base/SIB). These MIB investments provide enterprise funding to strengthen the MIB to support a generational increase in submarine demand and includes supplier development, shipbuilder/supplier infrastructure, workforce development, technology opportunities, and strategic outsourcing. Investments are targeted to support uplift of the MIB to achieve a "1+2 " Production Cadence, strengthening the MIB and reprioritizing/growing infrastructure to support new construction goals and increased demand as well as improved maintenance and sustainment for the submarine fleet. The MIB funding profile reflects the funding provided by the Indo-Pacific Supplemental Appropriations Act, 2024 ($1,955M) to support improvements to the MIB. FY2025 Plans includes supplier development Congressional adds +$5M for explosion welding facilities and +$18.5M for tube/propulsor facilitization. In August 2020, the COLUMBIA Class program completed its Construction Authorization In Progress Review (IPR). The Milestone Decision Authority (MDA) approved the program for entry into Build I construction on 28 August 2020, pending FY2021 congressional authorization and appropriation. As a result of the IPR, the FY2022 budget submission reflected SSBN 826-837 requirements aligned to the NAVSEA 05C's 2020 cost estimate plus additional funding for SSBN 826 based on the CAPE Lead Ship Assessment (LSA) cost estimate (+$155M FY2022-FY2023). At the COLUMBIA Program Semi-Annual IPR held on August 30, 2021, the MDA directed COLUMBIA to be funded to the program baseline, including IEP funding. FY2026 reflects funding to the NAVSEA 05C's 2023 cost estimate (including impacts from inflation) as well as to the results of preliminary Build II contract negotiations for basic construction costs. The Build II preliminary negotiations accounts for anticipated cost growth based on current vendor proposals, current shipbuilder performance, and inflation. The Program is completing an updated cost estimate and CAPE Independent Cost Estimate (ICE) to support Build II contract negotiation and award. The IEP funding leverages Congressional authorities and is aligned to OSD and Navy direction to execute COLUMBIA Class schedules needed to accelerate ship delivery schedules to reduce the strategic deterrence coverage gaps during transition from OHIO SSBNs to CLB SSBNs and the transition from D5LE to D5LE2 missiles. It is crucial to maintain force structure necessary to meet USSTRATCOM requirements for Sea-Based Strategic Deterrence (SBSD). Total MIB funding of $1,352M in FY2026 is accounted for in SSBN 837 Plans Costs P-5c Cost Category to ensure it is visible and can be appropriately tracked and managed. Since the FY2025 submission, FY2026 was reduced by $50M and rephased later into the FYDP FY2021 was the year of authorization for the lead ship, DISTRICT OF COLUMBIA (SSBN 826), and was a new start program due to FY2021 being the first year of incremental full funding. FY2022 and FY2023 were the second and third year of full funding for lead ship, DISTRICT OF COLUMBIA. FY2024 was the year of authorization for the second ship, WISCONSIN (SSBN 827), and first year of incremental funding for the second ship; FY2025 is the second year of incremental funding. FY2026 will be the year of authorization and the first year of incremental funding for the third ship. The budget request supports continued detailed design and construction of CFE and GFE systems to build, test, outfit, and deliver SSBN 828 and later ships. Funding also supports Continuous Production of Missile Tubes, Advance Construction (AC), EOQ for Multi-Program Procurement, Continuous Production of Shipyard Manufactured Items, and Supplier Development to reduce COLUMBIA Class construction schedule risk executed in accordance with enhanced acquisition authorities contained within the National Sea-Based Deterrence Fund (NSBDF), 10 U.S.C. 2218a. The Navy executed a Build I contract for the first two COLUMBIA class submarines (SSBN 826 and SSBN 827), detailed below. The Navy's FY2026 budget was altered to reflect three-year incremental funding profile for all COLUMBIA (CLB) Build II Ships and continues for rest of class. This results in a reduction of $3.1B in FY2026 (shifted into follow years). This incremental full funding profile supports the phased requirements to meet the objective SSBN 828 delivery date. A Contract Modification for ongoing design/advance construction efforts was awarded on 22 June 2020, which also included the Build I Option for the First Two Ships. This was a Pre-Priced Option for the two ships, SSBN 826 and SSBN 827, and associated design/support efforts. This was a modification of the current IPPD contract (N00024-17-C-2117) and is in line with the program's approved Acquisition Strategy. The program received authorization for SSBN 826 in FY2021, funded with three years of incremental funding in FY2021-2023, and SSBN 827 was authorized in FY2024, funded with two years of incremental funding in FY2024-2025. In December 2022, program awarded an additional pre-priced contract modification of IPPD to support Build II/III Advance Procurement / Advance Construction, EOQ for Build II, and MIB efforts. CLB and VIRGINIA Class (VCS) Programs are executing an innovative contracting approach (similar to CLB Build I) which will coordinate CLB Build II with VCS new construction contracting efforts (VCS FY2024 ships and Block VI (FY2025-2029)) to maximize efficiency and stability across the industrial base. The coordination of three separate contract actions eliminates redundant effort by negotiating multiple contracts simultaneously while allowing the shipbuilders to place material orders for multiple ships in concert with VCS which improves stability for supplier base to de-risk schedules. Since the FY2025 submission, the COLUMBIA Class Program continues investment in initiatives to reduce construction schedule risk and enable cost savings (Multi-Program Material Procurement (MPMP), Continuous Production (CP) of Missile Tubes/Outfitting, Ordnance Systems and Shipyard Manufactured Components, Economic Order Quantity efforts, and Advance Construction). Increased investment in Strategic Weapons System (SWS) Shipboard Systems EOQ and Continuous Production leverages additional opportunities to mitigate obsolescence and construction schedule risks and realize additional cost savings outside of the FYDP. The Navy in FY2026 continues to fund additional IEP initiatives (EOQ/MPMP, CP, Missile Tube Outfitting, AC/AP, and Production Backup Units) which is crucial to de-risk and execute IEP Objective schedules. Total class cost savings is $2,010M. Details are contained in the P-10. The first Missile Tube Module (MTM) is funded through RDTEN Program Element 0603595N for $584M; additional $195M funds added due to MTM performance growth in the FY2026 submission.
A6: SCN | B6: Procurement | D6: COLUMBIA Class Submarine - SFF for FY 2024 | E6: 1 | F6: Full ship DD&C | J6: 3364835 | V6: [SUB] | W6: 1045 / COLUMBIA Class Submarine | X6: USN | Y6: Combatant Ships | Z6: Submarines | AA6: SSBN | AB6: P-1 Exhibit > BA 01 > Line 1 SFF | AC6: 12 | AF6: 1045 | AI6: Maritime Platforms & Systems | AJ6: Submarines - SSBN/SSGN | AK6: MISSION: Strategic Deterrence. The COLUMBIA Class Program is an Acquisition Category (ACAT) ID Major Defense Acquisition Program (MDAP) to design, construct, and deliver a replacement for the OHIO Class Fleet Ballistic Missile Submarines (SSBNs), which begins retiring at a rate of one per year beginning in 2027. The mission of the COLUMBIA SSBN is to maintain an appropriate state of readiness to assist in deterring nuclear attack on the United States and its allies. In the event deterrence should fail, the force must be capable of launching missiles against pre-planned or adaptively planned targets. To fulfill this mission COLUMBIA SSBNs must be capable of performing extended strategic deterrent patrols without requiring assistance or replenishment. It does not have a requirement for additional capabilities or other missions unrelated to survivable strategic nuclear deterrence. Armament: Torpedo Tubes Ballistic Missile Tubes Major Electronics: Trident D5 Strategic Weapons System Command, Control, Communications and Intelligence System - Open System Architecture - Twenty-three Subsystems Note: The FY 2026 request for COLUMBIA Class Submarine includes $8,994,594 thousand of discretionary funding and $1,925,892 thousand of mandatory (reconciliation) funding for a total of $10,920,486 thousand. While the total FY 2026 discretionary funding decreased by $1,426,814 million when compared to the FY 2026 funding in the FY 2025 submission ($10,421,408 thousand), the overall funding (mandatory plus discretionary) for COLUMBIA Class Submarine increased by $499,078 thousand when compared to the FY 2026 funding in the FY 2025 submission. FY2026 is the first year of incremental full funding for the third ship, SSBN 828. Additionally, FY2026 funds the COLUMBIA Class Program to the NAVSEA 05C's 2023 cost estimate and preliminary Build II (SSBN 828-832) contract negotiations. The FY2026 budget and P5 breakout also includes Cost to Complete for Build I (SSBN 826-827), however, funding is reflected in FY2027-2030. The budget also includes continuing Integrated Enterprise Plan (IEP) funding initiatives, material procurement for future ships, and funding for the Maritime Industrial Base (MIB) (previously referred to as the Submarine Industrial Base/SIB). These MIB investments provide enterprise funding to strengthen the MIB to support a generational increase in submarine demand and includes supplier development, shipbuilder/supplier infrastructure, workforce development, technology opportunities, and strategic outsourcing. Investments are targeted to support uplift of the MIB to achieve a "1+2 " Production Cadence, strengthening the MIB and reprioritizing/growing infrastructure to support new construction goals and increased demand as well as improved maintenance and sustainment for the submarine fleet. The MIB funding profile reflects the funding provided by the Indo-Pacific Supplemental Appropriations Act, 2024 ($1,955M) to support improvements to the MIB. FY2025 Plans includes supplier development Congressional adds +$5M for explosion welding facilities and +$18.5M for tube/propulsor facilitization. In August 2020, the COLUMBIA Class program completed its Construction Authorization In Progress Review (IPR). The Milestone Decision Authority (MDA) approved the program for entry into Build I construction on 28 August 2020, pending FY2021 congressional authorization and appropriation. As a result of the IPR, the FY2022 budget submission reflected SSBN 826-837 requirements aligned to the NAVSEA 05C's 2020 cost estimate plus additional funding for SSBN 826 based on the CAPE Lead Ship Assessment (LSA) cost estimate (+$155M FY2022-FY2023). At the COLUMBIA Program Semi-Annual IPR held on August 30, 2021, the MDA directed COLUMBIA to be funded to the program baseline, including IEP funding. FY2026 reflects funding to the NAVSEA 05C's 2023 cost estimate (including impacts from inflation) as well as to the results of preliminary Build II contract negotiations for basic construction costs. The Build II preliminary negotiations accounts for anticipated cost growth based on current vendor proposals, current shipbuilder performance, and inflation. The Program is completing an updated cost estimate and CAPE Independent Cost Estimate (ICE) to support Build II contract negotiation and award. The IEP funding leverages Congressional authorities and is aligned to OSD and Navy direction to execute COLUMBIA Class schedules needed to accelerate ship delivery schedules to reduce the strategic deterrence coverage gaps during transition from OHIO SSBNs to CLB SSBNs and the transition from D5LE to D5LE2 missiles. It is crucial to maintain force structure necessary to meet USSTRATCOM requirements for Sea-Based Strategic Deterrence (SBSD). Total MIB funding of $1,352M in FY2026 is accounted for in SSBN 837 Plans Costs P-5c Cost Category to ensure it is visible and can be appropriately tracked and managed. Since the FY2025 submission, FY2026 was reduced by $50M and rephased later into the FYDP FY2021 was the year of authorization for the lead ship, DISTRICT OF COLUMBIA (SSBN 826), and was a new start program due to FY2021 being the first year of incremental full funding. FY2022 and FY2023 were the second and third year of full funding for lead ship, DISTRICT OF COLUMBIA. FY2024 was the year of authorization for the second ship, WISCONSIN (SSBN 827), and first year of incremental funding for the second ship; FY2025 is the second year of incremental funding. FY2026 will be the year of authorization and the first year of incremental funding for the third ship. The budget request supports continued detailed design and construction of CFE and GFE systems to build, test, outfit, and deliver SSBN 828 and later ships. Funding also supports Continuous Production of Missile Tubes, Advance Construction (AC), EOQ for Multi-Program Procurement, Continuous Production of Shipyard Manufactured Items, and Supplier Development to reduce COLUMBIA Class construction schedule risk executed in accordance with enhanced acquisition authorities contained within the National Sea-Based Deterrence Fund (NSBDF), 10 U.S.C. 2218a. The Navy executed a Build I contract for the first two COLUMBIA class submarines (SSBN 826 and SSBN 827), detailed below. The Navy's FY2026 budget was altered to reflect three-year incremental funding profile for all COLUMBIA (CLB) Build II Ships and continues for rest of class. This results in a reduction of $3.1B in FY2026 (shifted into follow years). This incremental full funding profile supports the phased requirements to meet the objective SSBN 828 delivery date. A Contract Modification for ongoing design/advance construction efforts was awarded on 22 June 2020, which also included the Build I Option for the First Two Ships. This was a Pre-Priced Option for the two ships, SSBN 826 and SSBN 827, and associated design/support efforts. This was a modification of the current IPPD contract (N00024-17-C-2117) and is in line with the program's approved Acquisition Strategy. The program received authorization for SSBN 826 in FY2021, funded with three years of incremental funding in FY2021-2023, and SSBN 827 was authorized in FY2024, funded with two years of incremental funding in FY2024-2025. In December 2022, program awarded an additional pre-priced contract modification of IPPD to support Build II/III Advance Procurement / Advance Construction, EOQ for Build II, and MIB efforts. CLB and VIRGINIA Class (VCS) Programs are executing an innovative contracting approach (similar to CLB Build I) which will coordinate CLB Build II with VCS new construction contracting efforts (VCS FY2024 ships and Block VI (FY2025-2029)) to maximize efficiency and stability across the industrial base. The coordination of three separate contract actions eliminates redundant effort by negotiating multiple contracts simultaneously while allowing the shipbuilders to place material orders for multiple ships in concert with VCS which improves stability for supplier base to de-risk schedules. Since the FY2025 submission, the COLUMBIA Class Program continues investment in initiatives to reduce construction schedule risk and enable cost savings (Multi-Program Material Procurement (MPMP), Continuous Production (CP) of Missile Tubes/Outfitting, Ordnance Systems and Shipyard Manufactured Components, Economic Order Quantity efforts, and Advance Construction). Increased investment in Strategic Weapons System (SWS) Shipboard Systems EOQ and Continuous Production leverages additional opportunities to mitigate obsolescence and construction schedule risks and realize additional cost savings outside of the FYDP. The Navy in FY2026 continues to fund additional IEP initiatives (EOQ/MPMP, CP, Missile Tube Outfitting, AC/AP, and Production Backup Units) which is crucial to de-risk and execute IEP Objective schedules. Total class cost savings is $2,010M. Details are contained in the P-10. The first Missile Tube Module (MTM) is funded through RDTEN Program Element 0603595N for $584M; additional $195M funds added due to MTM performance growth in the FY2026 submission.
A7: SCN | B7: Procurement | D7: COLUMBIA Class Submarine - Net Procurement FY 2026 | E7: 1 | F7: Full ship DD&C | L7: 3928828 | N7: 3928828 | V7: [SUB] | W7: 1045 / COLUMBIA Class Submarine | X7: USN | Y7: Combatant Ships | Z7: Submarines | AA7: SSBN | AB7: P-1 Exhibit > BA 01 > Line 1 Net | AC7: 12 | AF7: 1045 | AI7: Maritime Platforms & Systems | AJ7: Submarines - SSBN/SSGN | AK7: MISSION: Strategic Deterrence. The COLUMBIA Class Program is an Acquisition Category (ACAT) ID Major Defense Acquisition Program (MDAP) to design, construct, and deliver a replacement for the OHIO Class Fleet Ballistic Missile Submarines (SSBNs), which begins retiring at a rate of one per year beginning in 2027. The mission of the COLUMBIA SSBN is to maintain an appropriate state of readiness to assist in deterring nuclear attack on the United States and its allies. In the event deterrence should fail, the force must be capable of launching missiles against pre-planned or adaptively planned targets. To fulfill this mission COLUMBIA SSBNs must be capable of performing extended strategic deterrent patrols without requiring assistance or replenishment. It does not have a requirement for additional capabilities or other missions unrelated to survivable strategic nuclear deterrence. Armament: Torpedo Tubes Ballistic Missile Tubes Major Electronics: Trident D5 Strategic Weapons System Command, Control, Communications and Intelligence System - Open System Architecture - Twenty-three Subsystems Note: The FY 2026 request for COLUMBIA Class Submarine includes $8,994,594 thousand of discretionary funding and $1,925,892 thousand of mandatory (reconciliation) funding for a total of $10,920,486 thousand. While the total FY 2026 discretionary funding decreased by $1,426,814 million when compared to the FY 2026 funding in the FY 2025 submission ($10,421,408 thousand), the overall funding (mandatory plus discretionary) for COLUMBIA Class Submarine increased by $499,078 thousand when compared to the FY 2026 funding in the FY 2025 submission. FY2026 is the first year of incremental full funding for the third ship, SSBN 828. Additionally, FY2026 funds the COLUMBIA Class Program to the NAVSEA 05C's 2023 cost estimate and preliminary Build II (SSBN 828-832) contract negotiations. The FY2026 budget and P5 breakout also includes Cost to Complete for Build I (SSBN 826-827), however, funding is reflected in FY2027-2030. The budget also includes continuing Integrated Enterprise Plan (IEP) funding initiatives, material procurement for future ships, and funding for the Maritime Industrial Base (MIB) (previously referred to as the Submarine Industrial Base/SIB). These MIB investments provide enterprise funding to strengthen the MIB to support a generational increase in submarine demand and includes supplier development, shipbuilder/supplier infrastructure, workforce development, technology opportunities, and strategic outsourcing. Investments are targeted to support uplift of the MIB to achieve a "1+2 " Production Cadence, strengthening the MIB and reprioritizing/growing infrastructure to support new construction goals and increased demand as well as improved maintenance and sustainment for the submarine fleet. The MIB funding profile reflects the funding provided by the Indo-Pacific Supplemental Appropriations Act, 2024 ($1,955M) to support improvements to the MIB. FY2025 Plans includes supplier development Congressional adds +$5M for explosion welding facilities and +$18.5M for tube/propulsor facilitization. In August 2020, the COLUMBIA Class program completed its Construction Authorization In Progress Review (IPR). The Milestone Decision Authority (MDA) approved the program for entry into Build I construction on 28 August 2020, pending FY2021 congressional authorization and appropriation. As a result of the IPR, the FY2022 budget submission reflected SSBN 826-837 requirements aligned to the NAVSEA 05C's 2020 cost estimate plus additional funding for SSBN 826 based on the CAPE Lead Ship Assessment (LSA) cost estimate (+$155M FY2022-FY2023). At the COLUMBIA Program Semi-Annual IPR held on August 30, 2021, the MDA directed COLUMBIA to be funded to the program baseline, including IEP funding. FY2026 reflects funding to the NAVSEA 05C's 2023 cost estimate (including impacts from inflation) as well as to the results of preliminary Build II contract negotiations for basic construction costs. The Build II preliminary negotiations accounts for anticipated cost growth based on current vendor proposals, current shipbuilder performance, and inflation. The Program is completing an updated cost estimate and CAPE Independent Cost Estimate (ICE) to support Build II contract negotiation and award. The IEP funding leverages Congressional authorities and is aligned to OSD and Navy direction to execute COLUMBIA Class schedules needed to accelerate ship delivery schedules to reduce the strategic deterrence coverage gaps during transition from OHIO SSBNs to CLB SSBNs and the transition from D5LE to D5LE2 missiles. It is crucial to maintain force structure necessary to meet USSTRATCOM requirements for Sea-Based Strategic Deterrence (SBSD). Total MIB funding of $1,352M in FY2026 is accounted for in SSBN 837 Plans Costs P-5c Cost Category to ensure it is visible and can be appropriately tracked and managed. Since the FY2025 submission, FY2026 was reduced by $50M and rephased later into the FYDP FY2021 was the year of authorization for the lead ship, DISTRICT OF COLUMBIA (SSBN 826), and was a new start program due to FY2021 being the first year of incremental full funding. FY2022 and FY2023 were the second and third year of full funding for lead ship, DISTRICT OF COLUMBIA. FY2024 was the year of authorization for the second ship, WISCONSIN (SSBN 827), and first year of incremental funding for the second ship; FY2025 is the second year of incremental funding. FY2026 will be the year of authorization and the first year of incremental funding for the third ship. The budget request supports continued detailed design and construction of CFE and GFE systems to build, test, outfit, and deliver SSBN 828 and later ships. Funding also supports Continuous Production of Missile Tubes, Advance Construction (AC), EOQ for Multi-Program Procurement, Continuous Production of Shipyard Manufactured Items, and Supplier Development to reduce COLUMBIA Class construction schedule risk executed in accordance with enhanced acquisition authorities contained within the National Sea-Based Deterrence Fund (NSBDF), 10 U.S.C. 2218a. The Navy executed a Build I contract for the first two COLUMBIA class submarines (SSBN 826 and SSBN 827), detailed below. The Navy's FY2026 budget was altered to reflect three-year incremental funding profile for all COLUMBIA (CLB) Build II Ships and continues for rest of class. This results in a reduction of $3.1B in FY2026 (shifted into follow years). This incremental full funding profile supports the phased requirements to meet the objective SSBN 828 delivery date. A Contract Modification for ongoing design/advance construction efforts was awarded on 22 June 2020, which also included the Build I Option for the First Two Ships. This was a Pre-Priced Option for the two ships, SSBN 826 and SSBN 827, and associated design/support efforts. This was a modification of the current IPPD contract (N00024-17-C-2117) and is in line with the program's approved Acquisition Strategy. The program received authorization for SSBN 826 in FY2021, funded with three years of incremental funding in FY2021-2023, and SSBN 827 was authorized in FY2024, funded with two years of incremental funding in FY2024-2025. In December 2022, program awarded an additional pre-priced contract modification of IPPD to support Build II/III Advance Procurement / Advance Construction, EOQ for Build II, and MIB efforts. CLB and VIRGINIA Class (VCS) Programs are executing an innovative contracting approach (similar to CLB Build I) which will coordinate CLB Build II with VCS new construction contracting efforts (VCS FY2024 ships and Block VI (FY2025-2029)) to maximize efficiency and stability across the industrial base. The coordination of three separate contract actions eliminates redundant effort by negotiating multiple contracts simultaneously while allowing the shipbuilders to place material orders for multiple ships in concert with VCS which improves stability for supplier base to de-risk schedules. Since the FY2025 submission, the COLUMBIA Class Program continues investment in initiatives to reduce construction schedule risk and enable cost savings (Multi-Program Material Procurement (MPMP), Continuous Production (CP) of Missile Tubes/Outfitting, Ordnance Systems and Shipyard Manufactured Components, Economic Order Quantity efforts, and Advance Construction). Increased investment in Strategic Weapons System (SWS) Shipboard Systems EOQ and Continuous Production leverages additional opportunities to mitigate obsolescence and construction schedule risks and realize additional cost savings outside of the FYDP. The Navy in FY2026 continues to fund additional IEP initiatives (EOQ/MPMP, CP, Missile Tube Outfitting, AC/AP, and Production Backup Units) which is crucial to de-risk and execute IEP Objective schedules. Total class cost savings is $2,010M. Details are contained in the P-10. The first Missile Tube Module (MTM) is funded through RDTEN Program Element 0603595N for $584M; additional $195M funds added due to MTM performance growth in the FY2026 submission.
A8: SCN | B8: Procurement | C8: 1045 | D8: COLUMBIA Class Submarine Advance Procurement (CY) | E8: 1 | F8: Advance procurement / LLTM | J8: 6215939 | L8: 5065766 | M8: 1925892 | N8: 6991658 | P8: 0 | Q8: 5350766 | R8: 5350766 | S8: 4763342 | T8: 205700 | U8: 4969042 | X8: USN | Y8: Combatant Ships | Z8: Submarines | AA8: SSBN | AB8: P-40 Exhibit > LI 1045 AP > COLUMBIA Class Submarine Advance Procurement | AC8: 57 | AF8: 1045 | AI8: Maritime Platforms & Systems | AJ8: Submarines - SSBN/SSGN | AK8: MISSION: Strategic Deterrence. The COLUMBIA Class Program is an Acquisition Category (ACAT) ID Major Defense Acquisition Program (MDAP) to design, construct, and deliver a replacement for the OHIO Class Fleet Ballistic Missile Submarines (SSBNs), which begins retiring at a rate of one per year beginning in 2027. The mission of the COLUMBIA SSBN is to maintain an appropriate state of readiness to assist in deterring nuclear attack on the United States and its allies. In the event deterrence should fail, the force must be capable of launching missiles against pre-planned or adaptively planned targets. To fulfill this mission COLUMBIA SSBNs must be capable of performing extended strategic deterrent patrols without requiring assistance or replenishment. It does not have a requirement for additional capabilities or other missions unrelated to survivable strategic nuclear deterrence. Armament: Torpedo Tubes Ballistic Missile Tubes Major Electronics: Trident D5 Strategic Weapons System Command, Control, Communications and Intelligence System - Open System Architecture - Twenty-three Subsystems Note: The FY 2026 request for COLUMBIA Class Submarine includes $8,994,594 thousand of discretionary funding and $1,925,892 thousand of mandatory (reconciliation) funding for a total of $10,920,486 thousand. While the total FY 2026 discretionary funding decreased by $1,426,814 million when compared to the FY 2026 funding in the FY 2025 submission ($10,421,408 thousand), the overall funding (mandatory plus discretionary) for COLUMBIA Class Submarine increased by $499,078 thousand when compared to the FY 2026 funding in the FY 2025 submission. FY2026 is the first year of incremental full funding for the third ship, SSBN 828. Additionally, FY2026 funds the COLUMBIA Class Program to the NAVSEA 05C's 2023 cost estimate and preliminary Build II (SSBN 828-832) contract negotiations. The FY2026 budget and P5 breakout also includes Cost to Complete for Build I (SSBN 826-827), however, funding is reflected in FY2027-2030. The budget also includes continuing Integrated Enterprise Plan (IEP) funding initiatives, material procurement for future ships, and funding for the Maritime Industrial Base (MIB) (previously referred to as the Submarine Industrial Base/SIB). These MIB investments provide enterprise funding to strengthen the MIB to support a generational increase in submarine demand and includes supplier development, shipbuilder/supplier infrastructure, workforce development, technology opportunities, and strategic outsourcing. Investments are targeted to support uplift of the MIB to achieve a "1+2 " Production Cadence, strengthening the MIB and reprioritizing/growing infrastructure to support new construction goals and increased demand as well as improved maintenance and sustainment for the submarine fleet. The MIB funding profile reflects the funding provided by the Indo-Pacific Supplemental Appropriations Act, 2024 ($1,955M) to support improvements to the MIB. FY2025 Plans includes supplier development Congressional adds +$5M for explosion welding facilities and +$18.5M for tube/propulsor facilitization. In August 2020, the COLUMBIA Class program completed its Construction Authorization In Progress Review (IPR). The Milestone Decision Authority (MDA) approved the program for entry into Build I construction on 28 August 2020, pending FY2021 congressional authorization and appropriation. As a result of the IPR, the FY2022 budget submission reflected SSBN 826-837 requirements aligned to the NAVSEA 05C's 2020 cost estimate plus additional funding for SSBN 826 based on the CAPE Lead Ship Assessment (LSA) cost estimate (+$155M FY2022-FY2023). At the COLUMBIA Program Semi-Annual IPR held on August 30, 2021, the MDA directed COLUMBIA to be funded to the program baseline, including IEP funding. FY2026 reflects funding to the NAVSEA 05C's 2023 cost estimate (including impacts from inflation) as well as to the results of preliminary Build II contract negotiations for basic construction costs. The Build II preliminary negotiations accounts for anticipated cost growth based on current vendor proposals, current shipbuilder performance, and inflation. The Program is completing an updated cost estimate and CAPE Independent Cost Estimate (ICE) to support Build II contract negotiation and award. The IEP funding leverages Congressional authorities and is aligned to OSD and Navy direction to execute COLUMBIA Class schedules needed to accelerate ship delivery schedules to reduce the strategic deterrence coverage gaps during transition from OHIO SSBNs to CLB SSBNs and the transition from D5LE to D5LE2 missiles. It is crucial to maintain force structure necessary to meet USSTRATCOM requirements for Sea-Based Strategic Deterrence (SBSD). Total MIB funding of $1,352M in FY2026 is accounted for in SSBN 837 Plans Costs P-5c Cost Category to ensure it is visible and can be appropriately tracked and managed. Since the FY2025 submission, FY2026 was reduced by $50M and rephased later into the FYDP FY2021 was the year of authorization for the lead ship, DISTRICT OF COLUMBIA (SSBN 826), and was a new start program due to FY2021 being the first year of incremental full funding. FY2022 and FY2023 were the second and third year of full funding for lead ship, DISTRICT OF COLUMBIA. FY2024 was the year of authorization for the second ship, WISCONSIN (SSBN 827), and first year of incremental funding for the second ship; FY2025 is the second year of incremental funding. FY2026 will be the year of authorization and the first year of incremental funding for the third ship. The budget request supports continued detailed design and construction of CFE and GFE systems to build, test, outfit, and deliver SSBN 828 and later ships. Funding also supports Continuous Production of Missile Tubes, Advance Construction (AC), EOQ for Multi-Program Procurement, Continuous Production of Shipyard Manufactured Items, and Supplier Development to reduce COLUMBIA Class construction schedule risk executed in accordance with enhanced acquisition authorities contained within the National Sea-Based Deterrence Fund (NSBDF), 10 U.S.C. 2218a. The Navy executed a Build I contract for the first two COLUMBIA class submarines (SSBN 826 and SSBN 827), detailed below. The Navy's FY2026 budget was altered to reflect three-year incremental funding profile for all COLUMBIA (CLB) Build II Ships and continues for rest of class. This results in a reduction of $3.1B in FY2026 (shifted into follow years). This incremental full funding profile supports the phased requirements to meet the objective SSBN 828 delivery date. A Contract Modification for ongoing design/advance construction efforts was awarded on 22 June 2020, which also included the Build I Option for the First Two Ships. This was a Pre-Priced Option for the two ships, SSBN 826 and SSBN 827, and associated design/support efforts. This was a modification of the current IPPD contract (N00024-17-C-2117) and is in line with the program's approved Acquisition Strategy. The program received authorization for SSBN 826 in FY2021, funded with three years of incremental funding in FY2021-2023, and SSBN 827 was authorized in FY2024, funded with two years of incremental funding in FY2024-2025. In December 2022, program awarded an additional pre-priced contract modification of IPPD to support Build II/III Advance Procurement / Advance Construction, EOQ for Build II, and MIB efforts. CLB and VIRGINIA Class (VCS) Programs are executing an innovative contracting approach (similar to CLB Build I) which will coordinate CLB Build II with VCS new construction contracting efforts (VCS FY2024 ships and Block VI (FY2025-2029)) to maximize efficiency and stability across the industrial base. The coordination of three separate contract actions eliminates redundant effort by negotiating multiple contracts simultaneously while allowing the shipbuilders to place material orders for multiple ships in concert with VCS which improves stability for supplier base to de-risk schedules. Since the FY2025 submission, the COLUMBIA Class Program continues investment in initiatives to reduce construction schedule risk and enable cost savings (Multi-Program Material Procurement (MPMP), Continuous Production (CP) of Missile Tubes/Outfitting, Ordnance Systems and Shipyard Manufactured Components, Economic Order Quantity efforts, and Advance Construction). Increased investment in Strategic Weapons System (SWS) Shipboard Systems EOQ and Continuous Production leverages additional opportunities to mitigate obsolescence and construction schedule risks and realize additional cost savings outside of the FYDP. The Navy in FY2026 continues to fund additional IEP initiatives (EOQ/MPMP, CP, Missile Tube Outfitting, AC/AP, and Production Backup Units) which is crucial to de-risk and execute IEP Objective schedules. Total class cost savings is $2,010M. Details are contained in the P-10. The first Missile Tube Module (MTM) is funded through RDTEN Program Element 0603595N for $584M; additional $195M funds added due to MTM performance growth in the FY2026 submission.
A9: SCN | B9: Procurement | C9: 2001 | D9: Carrier Replacement Program | E9: 1 | F9: Full ship DD&C | G9: To provide credible, sustainable, independent forward presence during peacetime without access to land bases; operate as the cornerstone of a joint and/or allied maritime expeditionary force in response to crisis; and carry the war to the enemy through joint multi-mission offensive operations. The | I9: 1729021 | J9: 1359124 | L9: 1046700 | M9: 0 | N9: 1046700 | S9: 641907 | T9: 37000 | U9: 678907 | V9: [PARENT] | X9: USN | Y9: Combatant Ships | Z9: Aircraft Carriers | AA9: CVN | AB9: P-40 Exhibit > LI 2001 > Carrier Replacement Program | AC9: 73 | AF9: 2001 | AI9: Maritime Platforms & Systems | AJ9: Aircraft Carriers | AK9: To provide credible, sustainable, independent forward presence during peacetime without access to land bases; operate as the cornerstone of a joint and/or allied maritime expeditionary force in response to crisis; and carry the war to the enemy through joint multi-mission offensive operations. The Navy designed the FORD Class aircraft carrier with the warfighting capability essential for the 21st century, and the flexibility and resilience to rapidly adapt to emerging threats. The Ford class incorporates advances in technology such as a new reactor plant, propulsion system, electric plant, Electromagnetic Aircraft Launch System (EMALS), Advanced Arresting Gear (AAG), machinery control, and integrated warfare systems that increase lethality, while lowering life cycle costs through reductions in maintenance and manning requirements. Increased Service Life Allowances (SLA) for weight and stability enable future modernization and the ability to adapt to new missions over the ship's 50-year life cycle. CVN 80 and CVN 81 were awarded under a two-ship buy. CVN 80 is a separate contract line item under the same contract as CVN 81, which allows discrete hull costs to be captured. The CVN 80/81 construction contract is a Fixed Price Incentive (Firm Target) (FPIF) contract type that limits the Navy's liability and incentivizes the shipyard's best performance. The contract language guarantees a single technical baseline for both ships, which allows the shipyard to re-use engineering rollover products, minimize changes between the two ships and leverages economic order quantities for equipment and material procurement. The Advanced Procurement (AP) funding in FY 2026 is the first of 4 years of AP funding for CVN 82. CVN 81 was moved to BLI 2004 in accordance with the Department of Defense Appropriations Act, 2020.
A10: SCN | B10: Procurement | D10: Carrier Replacement - SFF for FY 2018 | E10: 1 | F10: Full ship DD&C | I10: 1104421 | J10: 1123124 | L10: 1046700 | N10: 1046700 | V10: [SUB] | W10: 2001 / Carrier Replacement Program | X10: USN | Y10: Combatant Ships | Z10: Aircraft Carriers | AA10: CVN | AB10: P-1 Exhibit > BA 02 > Line 5 SFF | AC10: 15 | AF10: 2001 | AI10: Maritime Platforms & Systems | AJ10: Aircraft Carriers | AK10: To provide credible, sustainable, independent forward presence during peacetime without access to land bases; operate as the cornerstone of a joint and/or allied maritime expeditionary force in response to crisis; and carry the war to the enemy through joint multi-mission offensive operations. The Navy designed the FORD Class aircraft carrier with the warfighting capability essential for the 21st century, and the flexibility and resilience to rapidly adapt to emerging threats. The Ford class incorporates advances in technology such as a new reactor plant, propulsion system, electric plant, Electromagnetic Aircraft Launch System (EMALS), Advanced Arresting Gear (AAG), machinery control, and integrated warfare systems that increase lethality, while lowering life cycle costs through reductions in maintenance and manning requirements. Increased Service Life Allowances (SLA) for weight and stability enable future modernization and the ability to adapt to new missions over the ship's 50-year life cycle. CVN 80 and CVN 81 were awarded under a two-ship buy. CVN 80 is a separate contract line item under the same contract as CVN 81, which allows discrete hull costs to be captured. The CVN 80/81 construction contract is a Fixed Price Incentive (Firm Target) (FPIF) contract type that limits the Navy's liability and incentivizes the shipyard's best performance. The contract language guarantees a single technical baseline for both ships, which allows the shipyard to re-use engineering rollover products, minimize changes between the two ships and leverages economic order quantities for equipment and material procurement. The Advanced Procurement (AP) funding in FY 2026 is the first of 4 years of AP funding for CVN 82. CVN 81 was moved to BLI 2004 in accordance with the Department of Defense Appropriations Act, 2020.
A11: SCN | B11: Procurement | D11: Carrier Replacement - Completion PY FY 2013 | E11: 1 | F11: Full ship DD&C | I11: 624600 | J11: 236000 | V11: [SUB] | W11: 2001 / Carrier Replacement Program | X11: USN | Y11: Combatant Ships | Z11: Aircraft Carriers | AA11: CVN | AB11: P-1 Exhibit > BA 02 > Line 5 CTC | AC11: 15 | AF11: 2001 | AI11: Maritime Platforms & Systems | AJ11: Aircraft Carriers | AK11: To provide credible, sustainable, independent forward presence during peacetime without access to land bases; operate as the cornerstone of a joint and/or allied maritime expeditionary force in response to crisis; and carry the war to the enemy through joint multi-mission offensive operations. The Navy designed the FORD Class aircraft carrier with the warfighting capability essential for the 21st century, and the flexibility and resilience to rapidly adapt to emerging threats. The Ford class incorporates advances in technology such as a new reactor plant, propulsion system, electric plant, Electromagnetic Aircraft Launch System (EMALS), Advanced Arresting Gear (AAG), machinery control, and integrated warfare systems that increase lethality, while lowering life cycle costs through reductions in maintenance and manning requirements. Increased Service Life Allowances (SLA) for weight and stability enable future modernization and the ability to adapt to new missions over the ship's 50-year life cycle. CVN 80 and CVN 81 were awarded under a two-ship buy. CVN 80 is a separate contract line item under the same contract as CVN 81, which allows discrete hull costs to be captured. The CVN 80/81 construction contract is a Fixed Price Incentive (Firm Target) (FPIF) contract type that limits the Navy's liability and incentivizes the shipyard's best performance. The contract language guarantees a single technical baseline for both ships, which allows the shipyard to re-use engineering rollover products, minimize changes between the two ships and leverages economic order quantities for equipment and material procurement. The Advanced Procurement (AP) funding in FY 2026 is the first of 4 years of AP funding for CVN 82. CVN 81 was moved to BLI 2004 in accordance with the Department of Defense Appropriations Act, 2020.
A12: SCN | B12: Procurement | C12: 2001 | D12: Carrier Replacement Program Advance Procurement (CY) | E12: 1 | F12: Advance procurement / LLTM | G12: Basic: Funding is required for procurement of the longest lead non-reactor propulsion plant, electric plant contractor furnished equipment and shipbuilder advance procurement / construction efforts necessary to support an efficient CVN 82 construction schedule. Advance Construction (AC) / Advance | L12: 612038 | M12: 0 | N12: 612038 | Q12: 612038 | R12: 612038 | S12: 1940566 | U12: 1940566 | X12: USN | Y12: Combatant Ships | Z12: Aircraft Carriers | AA12: CVN | AB12: P-40 Exhibit > LI 2001 AP > Carrier Replacement AP | AC12: 115 | AF12: 2001 | AI12: Maritime Platforms & Systems | AJ12: Aircraft Carriers | AK12: To provide credible, sustainable, independent forward presence during peacetime without access to land bases; operate as the cornerstone of a joint and/or allied maritime expeditionary force in response to crisis; and carry the war to the enemy through joint multi-mission offensive operations. The Navy designed the FORD Class aircraft carrier with the warfighting capability essential for the 21st century, and the flexibility and resilience to rapidly adapt to emerging threats. The Ford class incorporates advances in technology such as a new reactor plant, propulsion system, electric plant, Electromagnetic Aircraft Launch System (EMALS), Advanced Arresting Gear (AAG), machinery control, and integrated warfare systems that increase lethality, while lowering life cycle costs through reductions in maintenance and manning requirements. Increased Service Life Allowances (SLA) for weight and stability enable future modernization and the ability to adapt to new missions over the ship's 50-year life cycle. CVN 80 and CVN 81 were awarded under a two-ship buy. CVN 80 is a separate contract line item under the same contract as CVN 81, which allows discrete hull costs to be captured. The CVN 80/81 construction contract is a Fixed Price Incentive (Firm Target) (FPIF) contract type that limits the Navy's liability and incentivizes the shipyard's best performance. The contract language guarantees a single technical baseline for both ships, which allows the shipyard to re-use engineering rollover products, minimize changes between the two ships and leverages economic order quantities for equipment and material procurement. The Advanced Procurement (AP) funding in FY 2026 is the first of 4 years of AP funding for CVN 82. CVN 81 was moved to BLI 2004 in accordance with the Department of Defense Appropriations Act, 2020.
A13: SCN | B13: Procurement | C13: 2004 | D13: CVN-81 | E13: 1 | F13: Full ship DD&C | G13: To provide credible, sustainable, independent forward presence during peacetime without access to land bases; operate as the cornerstone of a joint and/or allied maritime expeditionary force in response to crisis; and carry the war to the enemy through joint multi-mission offensive operations. The | I13: 800492 | J13: 674930 | L13: 1622935 | M13: 0 | N13: 1622935 | S13: 1447882 | U13: 1447882 | X13: USN | Y13: Combatant Ships | Z13: Aircraft Carriers | AA13: CVN | AB13: P-40 Exhibit > LI 2004 > CVN-81 | AC13: 117 | AF13: 2004 | AI13: Maritime Platforms & Systems | AJ13: Aircraft Carriers | AK13: To provide credible, sustainable, independent forward presence during peacetime without access to land bases; operate as the cornerstone of a joint and/or allied maritime expeditionary force in response to crisis; and carry the war to the enemy through joint multi-mission offensive operations. The Navy designed the FORD Class aircraft carrier with the warfighting capability essential for the 21st century, and the flexibility and resilience to rapidly adapt to emerging threats. The Ford class incorporates advances in technology such as a new reactor plant, propulsion system, electric plant, Electromagnetic Aircraft Launch System (EMALS), Advanced Arresting Gear (AAG), machinery control, and integrated warfare systems that increase lethality, while lowering life cycle costs through reductions in maintenance and manning requirements. Increased Service Life Allowances (SLA) for weight and stability enable future modernization and the ability to adapt to new missions over the ship's 50-year life cycle. CVN 80 and CVN 81 were awarded under a two-ship buy. CVN 81 is a separate contract line item under the same contract as CVN 80, which allows discrete hull costs to be captured. The CVN 80/81 construction contract is a Fixed Price Incentive (Firm Target) (FPIF) contract type that limits the Navy's liability and incentivizes the shipyard's best performance. The contract language guarantees a single technical baseline for both ships, which allows the shipyard to re-use engineering rollover products, minimize changes between the two ships and leverages economic order quantities for equipment and material procurement.
A14: SCN | B14: Procurement | C14: 2013 | D14: Virginia Class Submarine | E14: 1 | F14: Full ship DD&C | G14: MISSION: To seek out and destroy enemy ships across a wide spectrum of tactical scenarios, working both independently and in concert with a battle group/other ships, providing Joint Commanders with early, accurate knowledge of the battlefield on which power may be projected from sea; covert | I14: 7298145 | J14: 9599908 | L14: 816705 | M14: 6518600 | N14: 7335305 | P14: 4600000 | Q14: 2740305 | R14: 7340305 | S14: 8402316 | U14: 8402316 | V14: [PARENT] | X14: USN | Y14: Combatant Ships | Z14: Submarines | AA14: SSN | AB14: P-40 Exhibit > LI 2013 > Virginia Class Submarine | AC14: 155 | AF14: 2013 | AI14: Maritime Platforms & Systems | AJ14: Submarines - SSN | AK14: MISSION: To seek out and destroy enemy ships across a wide spectrum of tactical scenarios, working both independently and in concert with a battle group/other ships, providing Joint Commanders with early, accurate knowledge of the battlefield on which power may be projected from sea; covert striking power against targets ashore; the capability to establish covertly an expeditionary force on land; and the maritime strength to destroy enemy naval forces and interdict seaborne commerce. NOTE: For VIRGINIA Class Submarine (VCS), the Department requests a total of $11,078,029 thousand and a total quantity of 2 ships. This request includes $3,943,521 thousand of discretionary and a quantity of 1 and $7,134,508 thousand and a quantity of 1 of mandatory for a total of $11,078,029 thousand and a quantity of 2. The mandatory funds one FY 2026 VCS as well as continued investments in nuclear shipbuilder productivity wage enhancements. The discretionary includes funds for one FY 2026 VCS, and advance procurement and economic order quantity funds for future VIRGINIA Class Submarines. Further information for this reconciliation request is provided in Section 20002 (Shipbuilding) of the Reconciliation Exhibit. The program is currently executing the fourth Multi-Year Procurement (MYP) (Block V) contract which was awarded on 2 December 2019, modified on 22 March 2021 to exercise an option for a tenth SSN, and subsequently modified on 30 April 2025 to include the FY 2024 eleventh and twelfth SSNs. The April 2025 modification includes funds received via the American Relief Act (ARA) of 2025 (H.R.10545) to support construction of the FY 2024 hulls ($1,950M) and FY 2025 hull ($1,528M), as well as investments in shipbuilder workforce support and infrastructure enhancements ($2,213M). Block V incorporates Acoustic Superiority (AS) modifications on all SSNs, and VIRGINIA Payload Module (VPM) beginning with SSN 803. All Block V SSNs will include modifications to provide enhanced capability and improved performance based upon efforts performed via RDT&E (PE 0604558N/Prj 1947). VPM is an 84-foot hull section with four additional payload tubes, each capable of carrying seven Tomahawk cruise missiles or various other payloads. VPM helps mitigate the loss of undersea strike capability with the retirement of the Service's four guided missile submarines (SSGNs) in the late-2020s. Funding associated with these changes to the baseline are shown in more detail on subsequent pages of these exhibits. The program is currently planning the fifth MYP (Block VI) contract for FY 2025 - FY 2029 procurements.
A15: SCN | B15: Procurement | D15: Virginia Class Sub - Net Procurement | E15: 1 | F15: Full ship DD&C | I15: 7129965 | J15: 7356904 | L15: 816705 | M15: 6518600 | N15: 7335305 | V15: [SUB] | W15: 2013 / Virginia Class Submarine | X15: USN | Y15: Combatant Ships | Z15: Submarines | AA15: SSN | AB15: P-1 Exhibit > BA 02 > Line 8 Net | AC15: 14 | AF15: 2013 | AI15: Maritime Platforms & Systems | AJ15: Submarines - SSN | AK15: MISSION: To seek out and destroy enemy ships across a wide spectrum of tactical scenarios, working both independently and in concert with a battle group/other ships, providing Joint Commanders with early, accurate knowledge of the battlefield on which power may be projected from sea; covert striking power against targets ashore; the capability to establish covertly an expeditionary force on land; and the maritime strength to destroy enemy naval forces and interdict seaborne commerce. NOTE: For VIRGINIA Class Submarine (VCS), the Department requests a total of $11,078,029 thousand and a total quantity of 2 ships. This request includes $3,943,521 thousand of discretionary and a quantity of 1 and $7,134,508 thousand and a quantity of 1 of mandatory for a total of $11,078,029 thousand and a quantity of 2. The mandatory funds one FY 2026 VCS as well as continued investments in nuclear shipbuilder productivity wage enhancements. The discretionary includes funds for one FY 2026 VCS, and advance procurement and economic order quantity funds for future VIRGINIA Class Submarines. Further information for this reconciliation request is provided in Section 20002 (Shipbuilding) of the Reconciliation Exhibit. The program is currently executing the fourth Multi-Year Procurement (MYP) (Block V) contract which was awarded on 2 December 2019, modified on 22 March 2021 to exercise an option for a tenth SSN, and subsequently modified on 30 April 2025 to include the FY 2024 eleventh and twelfth SSNs. The April 2025 modification includes funds received via the American Relief Act (ARA) of 2025 (H.R.10545) to support construction of the FY 2024 hulls ($1,950M) and FY 2025 hull ($1,528M), as well as investments in shipbuilder workforce support and infrastructure enhancements ($2,213M). Block V incorporates Acoustic Superiority (AS) modifications on all SSNs, and VIRGINIA Payload Module (VPM) beginning with SSN 803. All Block V SSNs will include modifications to provide enhanced capability and improved performance based upon efforts performed via RDT&E (PE 0604558N/Prj 1947). VPM is an 84-foot hull section with four additional payload tubes, each capable of carrying seven Tomahawk cruise missiles or various other payloads. VPM helps mitigate the loss of undersea strike capability with the retirement of the Service's four guided missile submarines (SSGNs) in the late-2020s. Funding associated with these changes to the baseline are shown in more detail on subsequent pages of these exhibits. The program is currently planning the fifth MYP (Block VI) contract for FY 2025 - FY 2029 procurements.
